Workbook

Sheet Tabelle2
A3: Zeilenbeschriftungen | B3: Anzahl von Die Entfernung zwischen dem Menschen im grauen Bereich und der Säule im blauen Bereich würde ich wie folgt einschätzen. []
A4: A001 | B4: 0.095238095
A5: A002 | B5: 0.23809524
A6: A003 | B6: 0.38095238
A7: A004 | B7: 0.23809524
A8: A005 | B8: 0.047619048
A9: Gesamtergebnis | B9: 1
A12: Zeilenbeschriftungen | B12: Anzahl von Wie weit entfernt ist die Säule im grünen Bereich von Ihrer aktuellen Position (aus Ihrer Sicht/POV)? []
A13: A001 | B13: 0.047619048
A14: A003 | B14: 0.23809524
A15: A004 | B15: 0.42857143
A16: A005 | B16: 0.28571429
A17: Gesamtergebnis | B17: 1
A19: Zeilenbeschriftungen | B19: Anzahl von Wie weit erscheint ihnen der Abstand der Kiste im grauen Bereich? []
A20: A003 | B20: 0.047619048
A21: A005 | B21: 0.95238095
A22: Gesamtergebnis | B22: 1
A24: Zeilenbeschriftungen | B24: Anzahl von Direkt nach dem Neustart (Reset) des Szenarios: Welches Objekt ist näher an Ihrer Startposition?
A25: A001 | B25: 0.95238095
A26: A004 | B26: 0.047619048
A27: Gesamtergebnis | B27: 1
A29: Zeilenbeschriftungen | B29: Anzahl von Wie weit entfernt ist die Säule im grünen Bereich von Ihrer aktuellen Position (aus Ihrer Sicht/POV)? []
A30: A001 | B30: 0.047619048
A31: A003 | B31: 0.23809524
A32: A004 | B32: 0.42857143
A33: A005 | B33: 0.28571429
A34: Gesamtergebnis | B34: 1

Sheet Auswertung_Umfrage_V2
B1: Allgemeine Fragen | G1: Szenario 1_P1 | N1: Szenario 2_P1 | U1: Szenario 3_P1 | AB1: Szenario 1_P2 | AG1: Szenario 2_P2 | AL1: Szenario 3_P2
A2: Antwort ID | B2: Wie alt sind Sie? | C2: Wie häufig nutzen Sie 3D-Inhalte oder 3D-Anwendungen? (z. B. 3D-Videospiele, 3D-Animationen in Filmen/Serien) | D2: Wie groß ist Ihre Bildschirmgröße, auf der Sie die Studie durchführen? | E2: Wie hoch ist ihre Downloadgeschwindigkeit, mit der sie die Szenarien ansehen? | F2: Hat der Computer/Laptop, mit dem sie die Studie durchführen, eine zusätzliche Grafikkarte (dedizierte Grafikkarte)? | G2: Bitte schauen Sie sich jetzt das erste Szenario an, und beantworte danach die folgenden Fragen Sie können jederzeit sich das Szenario nochmal ansehen, um die Fragen besser zu beantworten. | H2: Die Entfernung zwischen dem Menschen im grauen Bereich und der Säule im blauen Bereich würde ich wie folgt einschätzen. [] | I2: Wie weit entfernt ist die Säule im grünen Bereich von Ihrer aktuellen Position (aus Ihrer Sicht/POV)? [] | J2: Wie weit erscheint ihnen der Abstand der Kiste im grauen Bereich? [] | K2: Direkt nach dem Neustart (Reset) des Szenarios: Welches Objekt ist näher an Ihrer Startposition? | L2: Direkt nach dem Neustart (Reset) des Szenarios: Welches Objekt ist näher an Ihrer Startposition? | M2: Direkt nach dem Neustart (Reset) des Szenarios: Welches Objekt ist näher an Ihrer Startposition?2 | N2: Bitte schauen Sie sich jetzt das Zweite Szenario an, und beantworte danach die folgenden Fragen Sie können jederzeit sich das Szenario nochmal ansehen, um die Fragen besser zu beantworten. Bitte bewerten Sie dieses Szenario unabhängig von den vorherigen. Jede Szene kann eine andere Tiefenwirkung haben. | O2: Die Entfernung zwischen dem Menschen im grauen Bereich und der Säule im blauen Bereich würde ich wie folgt einschätzen. [] | P2: Wie weit entfernt ist die Säule im grünen Bereich von Ihrer aktuellen Position (aus Ihrer Sicht/POV)? [] | Q2: Wie weit erscheint ihnen der Abstand der Kiste im grauen Bereich? [] | R2: Direkt nach dem Neustart (Reset) des Szenarios: Welches Objekt ist näher an Ihrer Startposition? | S2: Direkt nach dem Neustart (Reset) des Szenarios: Welches Objekt ist näher an Ihrer Startposition? | T2: Direkt nach dem Neustart (Reset) des Szenarios: Welches Objekt ist näher an Ihrer Startposition? | U2: Bitte schauen Sie sich jetzt das Dritte Szenario an, und beantworte danach die folgenden Fragen Sie können jederzeit sich das Szenario nochmal ansehen, um die Fragen besser zu beantworten. Bitte bewerten Sie dieses Szenario unabhängig von den vorherigen. Jede Szene kann eine andere Tiefenwirkung haben. | V2: Die Entfernung zwischen dem Menschen im grauen Bereich und der Säule im blauen Bereich würde ich wie folgt einschätzen. [] | W2: Wie weit entfernt ist die Säule im grünen Bereich von Ihrer aktuellen Position (aus Ihrer Sicht/POV)? [] | X2: Wie weit erscheint ihnen der Abstand der Kiste im grauen Bereich? [] | Y2: Direkt nach dem Neustart (Reset) des Szenarios: Welches Objekt ist näher an Ihrer Startposition? | Z2: Direkt nach dem Neustart (Reset) des Szenarios: Welches Objekt ist näher an Ihrer Startposition? | AA2: Direkt nach dem Neustart (Reset) des Szenarios: Welches Objekt ist näher an Ihrer Startposition? | AB2: Bitte schauen Sie sich jetzt das erste Szenario an, und beantworte danach die folgenden Fragen Sie können jederzeit sich das Szenario nochmal ansehen, um die Fragen besser zu beantworten. Bitte bewerten Sie dieses Szenario unabhängig von den vorherigen. Jede Szene kann eine andere Tiefenwirkung haben. | AC2: Eine eindeutige und deutliche Tiefenwahrnehmung zwischen den Bereichen Grau, Grün und Blau ist klar erkennbar? [] | AD2: Beim Bewegen fallen Verzerrungen oder Verformungen der Umgebung stark auf. [] | AE2: Die räumliche Tiefenwahrnehmung wirkt realistisch. [] | AF2: Nach dem Laden läuft die Szene flüssig und ich habe kein Ruckeln oder ein eingefrorenes Bild. (Latenzen) [] | AG2: Bitte schauen Sie sich jetzt das erste Szenario an, und beantworte danach die folgenden Fragen Sie können jederzeit sich das Szenario nochmal ansehen, um die Fragen besser zu beantworten. Bitte bewerten Sie dieses Szenario unabhängig von den vorherigen. Jede Szene kann eine andere Tiefenwirkung haben. | AH2: Eine eindeutige und deutliche Tiefenwahrnehmung zwischen den Bereichen Grau, Grün und Blau ist klar erkennbar? [] | AI2: Beim Bewegen fallen Verzerrungen oder Verformungen der Umgebung stark auf. [] | AJ2: Die räumliche Tiefenwahrnehmung wirkt realistisch. [] | AK2: Nach dem Laden läuft die Szene flüssig und ich habe kein Ruckeln oder ein eingefrorenes Bild. (Latenzen) [] | AL2: Bitte schauen Sie sich jetzt das erste Szenario an, und beantworte danach die folgenden Fragen Sie können jederzeit sich das Szenario nochmal ansehen, um die Fragen besser zu beantworten. Bitte bewerten Sie dieses Szenario unabhängig von den vorherigen. Jede Szene kann eine andere Tiefenwirkung haben. | AM2: Eine eindeutige und deutliche Tiefenwahrnehmung zwischen den Bereichen Grau, Grün und Blau ist klar erkennbar? [] | AN2: Beim Bewegen fallen Verzerrungen oder Verformungen der Umgebung stark auf. [] | AO2: Die räumliche Tiefenwahrnehmung wirkt realistisch. [] | AP2: Nach dem Laden läuft die Szene flüssig und ich habe kein Ruckeln oder ein eingefrorenes Bild. (Latenzen) []
A3: 5 | B3: 28 | C3: 4 | D3: A006 | E3: A002 | F3: A001 | G3: A001 | H3: A005 | I3: A004 | J3: A005 | K3: A001 | L3: A004 | M3: A002 | N3: A001 | O3: A003 | P3: A004 | Q3: A005 | R3: A005 | S3: A004 | T3: A004 | U3: A001 | V3: A001 | W3: A003 | X3: A004 | Y3: A004 | Z3: A004 | AA3: A005 | AB3: A001 | AC3: A003 | AD3: A005 | AE3: A002 | AF3: A006 | AG3: A001 | AH3: A005 | AI3: A003 | AJ3: A004 | AK3: A007 | AL3: A001 | AM3: A005 | AN3: A005 | AO3: A005 | AP3: A004
A4: 7 | B4: 26 | C4: 2 | D4: A006 | E4: A004 | F4: A002 | G4: A001 | H4: A002 | I4: A004 | J4: A005 | K4: A001 | L4: A004 | M4: A002 | N4: A001 | O4: A003 | P4: A004 | Q4: A005 | R4: A006 | S4: A006 | T4: A005 | U4: A001 | V4: A003 | W4: A004 | X4: A005 | Y4: A004 | Z4: A006 | AA4: A005 | AB4: A001 | AC4: A006 | AD4: A007 | AE4: A004 | AF4: A007 | AG4: A001 | AH4: A007 | AI4: A001 | AJ4: A006 | AK4: A007 | AL4: A001 | AM4: A007 | AN4: A001 | AO4: A006 | AP4: A007
A5: 8 | B5: 26 | C5: 4 | D5: A007 | E5: A002 | F5: A001 | G5: A001 | H5: A003 | I5: A004 | J5: A005 | K5: A001 | L5: A001 | M5: A002 | N5: A001 | O5: A003 | P5: A003 | Q5: A005 | R5: A005 | S5: A006 | T5: A005 | U5: A001 | V5: A003 | W5: A004 | X5: A005 | Y5: A004 | Z5: A006 | AA5: A005 | AB5: A001 | AC5: A007 | AD5: A002 | AE5: A006 | AF5: A007 | AG5: A001 | AH5: A007 | AI5: A002 | AJ5: A004 | AK5: A007 | AL5: A001 | AM5: A007 | AN5: A002 | AO5: A006 | AP5: A007
A6: 9 | B6: 25 | C6: 3 | D6: A007 | E6: A002 | F6: A001 | G6: A001 | H6: A001 | I6: A001 | J6: A005 | K6: A001 | L6: A001 | M6: A002 | N6: A001 | O6: A003 | P6: A004 | Q6: A005 | R6: A006 | S6: A004 | T6: A006 | U6: A001 | V6: A005 | W6: A004 | X6: A005 | Y6: A004 | Z6: A006 | AA6: A005 | AB6: A001 | AC6: A006 | AD6: A005 | AE6: A001 | AF6: A001 | AG6: A001 | AH6: A004 | AI6: A001 | AJ6: A001 | AK6: A001 | AL6: A001 | AM6: A007 | AN6: A007 | AO6: A003 | AP6: A007
A7: 11 | B7: 27 | C7: 4 | D7: A007 | E7: A001 | F7: A001 | G7: A001 | H7: A003 | I7: A004 | J7: A005 | K7: A001 | L7: A001 | M7: A004 | N7: A001 | O7: A003 | P7: A004 | Q7: A005 | R7: A005 | S7: A006 | T7: A005 | U7: A001 | V7: A003 | W7: A004 | X7: A005 | Y7: A004 | Z7: A004 | AA7: A006 | AB7: A001 | AC7: A005 | AD7: A001 | AE7: A002 | AF7: A007 | AG7: A001 | AH7: A005 | AI7: A004 | AJ7: A002 | AK7: A006 | AL7: A001 | AM7: A005 | AN7: A001 | AO7: A002 | AP7: A004
A8: 12 | B8: 28 | C8: 1 | D8: A006 | E8: A001 | F8: A002 | G8: A001 | H8: A001 | I8: A003 | J8: A005 | K8: A001 | L8: A004 | M8: A002 | N8: A001 | O8: A002 | P8: A003 | Q8: A005 | R8: A006 | S8: A006 | T8: A005 | U8: A001 | V8: A002 | W8: A003 | X8: A005 | Y8: A004 | Z8: A004 | AA8: A005 | AB8: A001 | AC8: A007 | AD8: A001 | AE8: A007 | AF8: A007 | AG8: A001 | AH8: A005 | AI8: A005 | AJ8: A003 | AK8: A002 | AL8: A001 | AM8: A006 | AN8: A002 | AO8: A005 | AP8: A006
A9: 13 | B9: 25 | C9: 5 | D9: A007 | E9: A003 | F9: A001 | G9: A001 | H9: A004 | I9: A005 | J9: A005 | K9: A001 | L9: A002 | M9: A002 | N9: A001 | O9: A004 | P9: A005 | Q9: A005 | R9: A005 | S9: A005 | T9: A005 | U9: A001 | V9: A004 | W9: A005 | X9: A005 | Y9: A004 | Z9: A006 | AA9: A005 | AB9: A001 | AC9: A007 | AD9: A007 | AE9: A002 | AF9: A007 | AG9: A001 | AH9: A007 | AI9: A001 | AJ9: A006 | AK9: A007 | AL9: A001 | AM9: A007 | AN9: A001 | AO9: A007 | AP9: A007
A10: 15 | B10: 27 | C10: 1 | D10: A006 | E10: A005 | F10: A003 | G10: A001 | H10: A004 | I10: A005 | J10: A005 | K10: A001 | L10: A001 | M10: A002 | N10: A001 | O10: A002 | P10: A002 | Q10: A004 | R10: A005 | S10: A006 | T10: A005 | U10: A001 | V10: A001 | W10: A003 | X10: A004 | Y10: A004 | Z10: A004 | AA10: A005 | AB10: A001 | AC10: A005 | AD10: A004 | AE10: A004 | AF10: A006 | AG10: A001 | AH10: A006 | AI10: A004 | AJ10: A004 | AK10: A003 | AL10: A001 | AM10: A007 | AN10: A004 | AO10: A004 | AP10: A001
A11: 17 | B11: 29 | C11: 5 | D11: A007 | E11: A002 | F11: A001 | G11: A001 | H11: A003 | I11: A003 | J11: A005 | K11: A001 | L11: A004 | M11: A002 | N11: A001 | O11: A003 | P11: A004 | Q11: A005 | R11: A005 | S11: A005 | T11: A005 | U11: A001 | V11: A003 | W11: A004 | X11: A005 | Y11: A004 | Z11: A004 | AA11: A005 | AB11: A001 | AC11: A006 | AD11: A007 | AE11: A005 | AF11: A007 | AG11: A001 | AH11: A007 | AI11: A001 | AJ11: A007 | AK11: A007 | AL11: A001 | AM11: A007 | AN11: A001 | AO11: A007 | AP11: A007
A12: 19 | B12: 27 | C12: 2 | D12: A007 | E12: A003 | F12: A001 | G12: A001 | H12: A003 | I12: A004 | J12: A005 | K12: A001 | L12: A001 | M12: A002 | N12: A001 | O12: A003 | P12: A004 | Q12: A005 | R12: A005 | S12: A006 | T12: A005 | U12: A001 | V12: A003 | W12: A004 | X12: A005 | Y12: A004 | Z12: A004 | AA12: A005 | AB12: A001 | AC12: A003 | AD12: A006 | AE12: A002 | AF12: A007 | AG12: A001 | AH12: A005 | AI12: A001 | AJ12: A004 | AK12: A007 | AL12: A001 | AM12: A005 | AN12: A001 | AO12: A003 | AP12: A007
A13: 23 | B13: 33 | C13: 1 | D13: A006 | E13: A001 | F13: A001 | G13: A001 | H13: A004 | I13: A003 | J13: A005 | K13: A001 | L13: A001 | M13: A004 | N13: A001 | O13: A004 | P13: A003 | Q13: A005 | R13: A005 | S13: A005 | T13: A005 | U13: A001 | V13: A002 | W13: A004 | X13: A005 | Y13: A004 | Z13: A004 | AA13: A006 | AB13: A001 | AC13: A007 | AD13: A007 | AE13: A004 | AF13: A007 | AG13: A001 | AH13: A006 | AI13: A004 | AJ13: A003 | AK13: A007 | AL13: A001 | AM13: A007 | AN13: A001 | AO13: A007 | AP13: A007
A14: 26 | B14: 32 | C14: 3 | D14: A007 | E14: A002 | F14: A001 | G14: A001 | H14: A004 | I14: A005 | J14: A005 | K14: A001 | L14: A001 | M14: A002 | N14: A001 | O14: A002 | P14: A003 | Q14: A005 | R14: A005 | S14: A005 | T14: A005 | U14: A001 | V14: A002 | W14: A004 | X14: A005 | Y14: A004 | Z14: A004 | AA14: A005 | AB14: A001 | AC14: A002 | AD14: A007 | AE14: A003 | AF14: A004 | AG14: A001 | AH14: A007 | AI14: A002 | AJ14: A007 | AK14: A005 | AL14: A001 | AM14: A007 | AN14: A001 | AO14: A007 | AP14: A003
... A23: 39 | B23: 25 | C23: 5 | D23: A006 | E23: A002 | F23: A002 | G23: A001 | H23: A002 | I23: A005 | J23: A005 | K23: A004 | L23: A001 | M23: A002 | N23: A001 | O23: A003 | P23: A004 | Q23: A005 | R23: A003 | S23: A003 | T23: A004 | U23: A001 | V23: A006 | W23: A006 | X23: A005 | Y23: A004 | Z23: A006 | AA23: A005 | AB23: A001 | AC23: A006 | AD23: A004 | AE23: A005 | AF23: A007 | AG23: A001 | AH23: A005 | AI23: A002 | AJ23: A005 | AK23: A007 | AL23: A001 | AM23: A006 | AN23: A001 | AO23: A006 | AP23: A007
A24: Mittelwert M | B24: =AVERAGE(B3:B23) -> 27.809524 | C24: =AVERAGE(C3:C23) -> 3.5714286 | D24: =VALUE(MID(D3,2,99)) -> 6 | E24: =VALUE(MID(E3,2,99)) -> 2 | F24: =VALUE(MID(F3,2,99)) -> 1 | G24: =VALUE(MID(G3,2,99)) -> 1 | H24: =VALUE(MID(H3,2,99)) -> 5 | I24: =VALUE(MID(I3,2,99)) -> 4 | J24: =VALUE(MID(J3,2,99)) -> 5 | K24: =VALUE(MID(K3,2,99)) -> 1 | ... AP24: =VALUE(MID(AP3,2,99)) -> 4
A25: Wert übersetzt | H25: 5 = 0-5m | I25: 4 = 5-10m | J25: 5 = 0-5m | K25: 1 = Kiste Bett | L25: 4 = Gleich | M25: 2 = Säule GA | O25: 3 = 10-15m | P25: 4 = 5-10m | Q25: 5 = 0-5m | R25: 5 = Schild Gelb | S25: 4 = Ente Gelb | T25: 4 = Kiste Grau | V25: 1 = 20-25m | W25: 3 = 10-15m | X25: 4= 5-10m | Y25: 4 =Kiste Bett | Z25: 4 = Haustür | AA25: 5 = Säule GA
A26: Ground-Truth | H26: A002 | I26: A003 | J26: A005 | K26: A001 | L26: A001 | M26: A002 | O26: A002 | P26: A003 | Q26: A005 | R26: A005 | S26: A005 | T26: A005 | V26: A002 | W26: A003 | X26: A005 | Y26: A004 | Z26: A004 | AA26: A006
A27: Wert für menschen | H27: 2 = 15-20 m | I27: 3 = 10-15 | J27: 5 = 0-5m | K27: 1 = Kiste Bett | L27: 1 = Haustür | M27: 2= Säule im Grauen | O27: 18,45 m | P27: 13,3934 m | Q27: 4,5821m | R27: Schild Gelb | S27: gelbe Ente | T27: Die Säule im Grauen | V27: 18,45 m | W27: 13,3934 m | X27: 4,5821m | Y27: Kiste Bett | Z27: Haustür | AA27: Gleich nah | AW27: Ergebnisse: Metrische Fragen
A28: A001 | H28: =IFERROR(_xlfn.XLOOKUP(_xlfn.XLOOKUP($A28,H$3:H$23,$A$3:$A$23),utility!$A$3:$A$23,utility!H$3:H$23)&" | "&ROUND(COUNTIF(H$3:H$23,$A28)/21,3)*100&"%","") -> 20 - 25 m | 9,5% | I28: =IFERROR(_xlfn.XLOOKUP(_xlfn.XLOOKUP($A28,I$3:I$23,$A$3:$A$23),utility!$A$3:$A$23,utility!I$3:I$23)&" | "&ROUND(COUNTIF(I$3:I$23,$A28)/21,3)*100&"%","") -> 20-25m | 4,8% | J28: 0 | K28: =IFERROR(_xlfn.XLOOKUP(_xlfn.XLOOKUP($A28,K$3:K$23,$A$3:$A$23),utility!$A$3:$A$23,utility!K$3:K$23)&" | "&ROUND(COUNTIF(K$3:K$23,$A28)/21,3)*100&"%","") -> Die Kiste vor dem Bett im Holzraum | 95,2% | L28: =IFERROR(_xlfn.XLOOKUP(_xlfn.XLOOKUP($A28,L$3:L$23,$A$3:$A$23),utility!$A$3:$A$23,utility!L$3:L$23)&" | "&ROUND(COUNTIF(L$3:L$23,$A28)/21,3)*100&"%","") -> Die Haustür vom Haus | 71,4% | M28: =IFERROR(_xlfn.XLOOKUP(_xlfn.XLOOKUP($A28,M$3:M$23,$A$3:$A$23),utility!$A$3:$A$23,utility!M$3:M$23)&" | "&ROUND(COUNTIF(M$3:M$23,$A28)/21,3)*100&"%","") | N28: =IFERROR(_xlfn.XLOOKUP(_xlfn.XLOOKUP($A28,N$3:N$23,$A$3:$A$23),utility!$A$3:$A$23,utility!N$3:N$23)&" | "&ROUND(COUNTIF(N$3:N$23,$A28)/21,3)*100&"%","") -> Ja ich hab das szenario gesehen und weiter | 100% | O28: =IFERROR(_xlfn.XLOOKUP(_xlfn.XLOOKUP($A28,O$3:O$23,$A$3:$A$23),utility!$A$3:$A$23,utility!O$3:O$23)&" | "&ROUND(COUNTIF(O$3:O$23,$A28)/21,3)*100&"%","") -> 20-25m | 4,8% | P28: =IFERROR(_xlfn.XLOOKUP(_xlfn.XLOOKUP($A28,P$3:P$23,$A$3:$A$23),utility!$A$3:$A$23,utility!P$3:P$23)&" | "&ROUND(COUNTIF(P$3:P$23,$A28)/21,3)*100&"%","") | Q28: =IFERROR(_xlfn.XLOOKUP(_xlfn.XLOOKUP($A28,Q$3:Q$23,$A$3:$A$23),utility!$A$3:$A$23,utility!Q$3:Q$23)&" | "&ROUND(COUNTIF(Q$3:Q$23,$A28)/21,3)*100&"%","") | R28: =IFERROR(_xlfn.XLOOKUP(_xlfn.XLOOKUP($A28,R$3:R$23,$A$3:$A$23),utility!$A$3:$A$23,utility!R$3:R$23)&" | "&ROUND(COUNTIF(R$3:R$23,$A28)/21,3)*100&"%","") | ... AP28: =IFERROR(_xlfn.XLOOKUP(_xlfn.XLOOKUP($A28,AP$3:AP$23,$A$3:$A$23),utility!$A$3:$A$23,utility!AP$3:AP$23)&" | "&ROUND(COUNTIF(AP$3:AP$23,$A28)/21,3)*100&"%","") -> 1 | 19% | AW28: Szenario | AX28: Phase | AY28: Anteil GT-Klasse | AZ28: Anteil GT +/-1 | BA28: Streuung
A29: A002 | H29: =IFERROR(_xlfn.XLOOKUP(_xlfn.XLOOKUP($A29,H$3:H$23,$A$3:$A$23),utility!$A$3:$A$23,utility!H$3:H$23)&" | "&ROUND(COUNTIF(H$3:H$23,$A29)/21,3)*100&"%","") -> 15 - 20 m | 23,8% | I29: 0 | J29: 0 | K29: =IFERROR(_xlfn.XLOOKUP(_xlfn.XLOOKUP($A29,K$3:K$23,$A$3:$A$23),utility!$A$3:$A$23,utility!K$3:K$23)&" | "&ROUND(COUNTIF(K$3:K$23,$A29)/21,3)*100&"%","") | L29: =IFERROR(_xlfn.XLOOKUP(_xlfn.XLOOKUP($A29,L$3:L$23,$A$3:$A$23),utility!$A$3:$A$23,utility!L$3:L$23)&" | "&ROUND(COUNTIF(L$3:L$23,$A29)/21,3)*100&"%","") -> Die gelbe Ente im Pavillon | 4,8% | M29: =IFERROR(_xlfn.XLOOKUP(_xlfn.XLOOKUP($A29,M$3:M$23,$A$3:$A$23),utility!$A$3:$A$23,utility!M$3:M$23)&" | "&ROUND(COUNTIF(M$3:M$23,$A29)/21,3)*100&"%","") -> Die Säule im grauen Bereich | 90,5% | N29: =IFERROR(_xlfn.XLOOKUP(_xlfn.XLOOKUP($A29,N$3:N$23,$A$3:$A$23),utility!$A$3:$A$23,utility!N$3:N$23)&" | "&ROUND(COUNTIF(N$3:N$23,$A29)/21,3)*100&"%","") | O29: =IFERROR(_xlfn.XLOOKUP(_xlfn.XLOOKUP($A29,O$3:O$23,$A$3:$A$23),utility!$A$3:$A$23,utility!O$3:O$23)&" | "&ROUND(COUNTIF(O$3:O$23,$A29)/21,3)*100&"%","") -> 15-20m | 33,3% | P29: =IFERROR(_xlfn.XLOOKUP(_xlfn.XLOOKUP($A29,P$3:P$23,$A$3:$A$23),utility!$A$3:$A$23,utility!P$3:P$23)&" | "&ROUND(COUNTIF(P$3:P$23,$A29)/21,3)*100&"%","") -> 15-20m | 9,5% | Q29: =IFERROR(_xlfn.XLOOKUP(_xlfn.XLOOKUP($A29,Q$3:Q$23,$A$3:$A$23),utility!$A$3:$A$23,utility!Q$3:Q$23)&" | "&ROUND(COUNTIF(Q$3:Q$23,$A29)/21,3)*100&"%","") | R29: =IFERROR(_xlfn.XLOOKUP(_xlfn.XLOOKUP($A29,R$3:R$23,$A$3:$A$23),utility!$A$3:$A$23,utility!R$3:R$23)&" | "&ROUND(COUNTIF(R$3:R$23,$A29)/21,3)*100&"%","") | ... AP29: =IFERROR(_xlfn.XLOOKUP(_xlfn.XLOOKUP($A29,AP$3:AP$23,$A$3:$A$23),utility!$A$3:$A$23,utility!AP$3:AP$23)&" | "&ROUND(COUNTIF(AP$3:AP$23,$A29)/21,3)*100&"%","") | AW29: S1 | AX29: P1 | AY29: =AVERAGE(_xlfn.TEXTAFTER(AX16,"| "),_xlfn.TEXTAFTER(AY17,"| "),_xlfn.TEXTAFTER(AZ19,"| ")) -> #N/A | AZ29: =AVERAGE(AX23,AY23,AZ23) -> #DIV/0! | BA29: =SUM(100%-AZ29) -> #DIV/0!
A30: A003 | H30: =IFERROR(_xlfn.XLOOKUP(_xlfn.XLOOKUP($A30,H$3:H$23,$A$3:$A$23),utility!$A$3:$A$23,utility!H$3:H$23)&" | "&ROUND(COUNTIF(H$3:H$23,$A30)/21,3)*100&"%","") -> 10 - 15 m | 38,1% | I30: =IFERROR(_xlfn.XLOOKUP(_xlfn.XLOOKUP($A30,I$3:I$23,$A$3:$A$23),utility!$A$3:$A$23,utility!I$3:I$23)&" | "&ROUND(COUNTIF(I$3:I$23,$A30)/21,3)*100&"%","") -> 10-15m | 23,8% | J30: =IFERROR(_xlfn.XLOOKUP(_xlfn.XLOOKUP($A30,J$3:J$23,$A$3:$A$23),utility!$A$3:$A$23,utility!J$3:J$23)&" | "&ROUND(COUNTIF(J$3:J$23,$A30)/21,3)*100&"%","") -> 10-15m | 4,8% | K30: =IFERROR(_xlfn.XLOOKUP(_xlfn.XLOOKUP($A30,K$3:K$23,$A$3:$A$23),utility!$A$3:$A$23,utility!K$3:K$23)&" | "&ROUND(COUNTIF(K$3:K$23,$A30)/21,3)*100&"%","") | L30: =IFERROR(_xlfn.XLOOKUP(_xlfn.XLOOKUP($A30,L$3:L$23,$A$3:$A$23),utility!$A$3:$A$23,utility!L$3:L$23)&" | "&ROUND(COUNTIF(L$3:L$23,$A30)/21,3)*100&"%","") | M30: =IFERROR(_xlfn.XLOOKUP(_xlfn.XLOOKUP($A30,M$3:M$23,$A$3:$A$23),utility!$A$3:$A$23,utility!M$3:M$23)&" | "&ROUND(COUNTIF(M$3:M$23,$A30)/21,3)*100&"%","") | N30: =IFERROR(_xlfn.XLOOKUP(_xlfn.XLOOKUP($A30,N$3:N$23,$A$3:$A$23),utility!$A$3:$A$23,utility!N$3:N$23)&" | "&ROUND(COUNTIF(N$3:N$23,$A30)/21,3)*100&"%","") | O30: =IFERROR(_xlfn.XLOOKUP(_xlfn.XLOOKUP($A30,O$3:O$23,$A$3:$A$23),utility!$A$3:$A$23,utility!O$3:O$23)&" | "&ROUND(COUNTIF(O$3:O$23,$A30)/21,3)*100&"%","") -> 10-15m | 47,6% | ... X30: =IFERROR(_xlfn.XLOOKUP(_xlfn.XLOOKUP($A30,X$3:X$23,$A$3:$A$23),utility!$A$3:$A$23,utility!X$3:X$23)&" | "&ROUND(COUNTIF(X$3:X$23,$A30)/21,3)*100&"%","") | Y30: 0 | Z30: =IFERROR(_xlfn.XLOOKUP(_xlfn.XLOOKUP($A30,Z$3:Z$23,$A$3:$A$23),utility!$A$3:$A$23,utility!Z$3:Z$23)&" | "&ROUND(COUNTIF(Z$3:Z$23,$A30)/21,3)*100&"%","") | AA30: =IFERROR(_xlfn.XLOOKUP(_xlfn.XLOOKUP($A30,AA$3:AA$23,$A$3:$A$23),utility!$A$3:$A$23,utility!AA$3:AA$23)&" | "&ROUND(COUNTIF(AA$3:AA$23,$A30)/21,3)*100&"%","") | AB30: =IFERROR(_xlfn.XLOOKUP(_xlfn.XLOOKUP($A30,AB$3:AB$23,$A$3:$A$23),utility!$A$3:$A$23,utility!AB$3:AB$23)&" | "&ROUND(COUNTIF(AB$3:AB$23,$A30)/21,3)*100&"%","") | AC30: =IFERROR(_xlfn.XLOOKUP(_xlfn.XLOOKUP($A30,AC$3:AC$23,$A$3:$A$23),utility!$A$3:$A$23,utility!AC$3:AC$23)&" | "&ROUND(COUNTIF(AC$3:AC$23,$A30)/21,3)*100&"%","") -> 3 | 19% | AD30: =IFERROR(_xlfn.XLOOKUP(_xlfn.XLOOKUP($A30,AD$3:AD$23,$A$3:$A$23),utility!$A$3:$A$23,utility!AD$3:AD$23)&" | "&ROUND(COUNTIF(AD$3:AD$23,$A30)/21,3)*100&"%","") | AE30: =IFERROR(_xlfn.XLOOKUP(_xlfn.XLOOKUP($A30,AE$3:AE$23,$A$3:$A$23),utility!$A$3:$A$23,utility!AE$3:AE$23)&" | "&ROUND(COUNTIF(AE$3:AE$23,$A30)/21,3)*100&"%","") -> 3 | 4,8% | AF30: =IFERROR(_xlfn.XLOOKUP(_xlfn.XLOOKUP($A30,AF$3:AF$23,$A$3:$A$23),utility!$A$3:$A$23,utility!AF$3:AF$23)&" | "&ROUND(COUNTIF(AF$3:AF$23,$A30)/21,3)*100&"%","") | AG30: =IFERROR(_xlfn.XLOOKUP(_xlfn.XLOOKUP($A30,AG$3:AG$23,$A$3:$A$23),utility!$A$3:$A$23,utility!AG$3:AG$23)&" | "&ROUND(COUNTIF(AG$3:AG$23,$A30)/21,3)*100&"%","") | ... AP30: =IFERROR(_xlfn.XLOOKUP(_xlfn.XLOOKUP($A30,AP$3:AP$23,$A$3:$A$23),utility!$A$3:$A$23,utility!AP$3:AP$23)&" | "&ROUND(COUNTIF(AP$3:AP$23,$A30)/21,3)*100&"%","") -> 3 | 4,8% | AW30: S2 | AX30: P1 | AY30: =AVERAGE(_xlfn.TEXTAFTER(BE16,"| "),_xlfn.TEXTAFTER(BF17,"| "),_xlfn.TEXTAFTER(BG19,"| ")) -> #N/A | AZ30: =AVERAGE(BE23,BF23,BG23) -> #DIV/0! | BA30: =SUM(100%-AZ30) -> #DIV/0!
A31: A004 | H31: =IFERROR(_xlfn.XLOOKUP(_xlfn.XLOOKUP($A31,H$3:H$23,$A$3:$A$23),utility!$A$3:$A$23,utility!H$3:H$23)&" | "&ROUND(COUNTIF(H$3:H$23,$A31)/21,3)*100&"%","") -> 5-10 m | 23,8% | I31: =IFERROR(_xlfn.XLOOKUP(_xlfn.XLOOKUP($A31,I$3:I$23,$A$3:$A$23),utility!$A$3:$A$23,utility!I$3:I$23)&" | "&ROUND(COUNTIF(I$3:I$23,$A31)/21,3)*100&"%","") -> 5-10m | 42,9% | J31: 0 | K31: =IFERROR(_xlfn.XLOOKUP(_xlfn.XLOOKUP($A31,K$3:K$23,$A$3:$A$23),utility!$A$3:$A$23,utility!K$3:K$23)&" | "&ROUND(COUNTIF(K$3:K$23,$A31)/21,3)*100&"%","") -> Die Objekte sind gleich nah | 4,8% | L31: =IFERROR(_xlfn.XLOOKUP(_xlfn.XLOOKUP($A31,L$3:L$23,$A$3:$A$23),utility!$A$3:$A$23,utility!L$3:L$23)&" | "&ROUND(COUNTIF(L$3:L$23,$A31)/21,3)*100&"%","") -> Die Objekte sind gleich nah | 23,8% | M31: =IFERROR(_xlfn.XLOOKUP(_xlfn.XLOOKUP($A31,M$3:M$23,$A$3:$A$23),utility!$A$3:$A$23,utility!M$3:M$23)&" | "&ROUND(COUNTIF(M$3:M$23,$A31)/21,3)*100&"%","") -> Die Objekte sind gleich nah | 9,5% | N31: =IFERROR(_xlfn.XLOOKUP(_xlfn.XLOOKUP($A31,N$3:N$23,$A$3:$A$23),utility!$A$3:$A$23,utility!N$3:N$23)&" | "&ROUND(COUNTIF(N$3:N$23,$A31)/21,3)*100&"%","") | O31: =IFERROR(_xlfn.XLOOKUP(_xlfn.XLOOKUP($A31,O$3:O$23,$A$3:$A$23),utility!$A$3:$A$23,utility!O$3:O$23)&" | "&ROUND(COUNTIF(O$3:O$23,$A31)/21,3)*100&"%","") -> 5-10m | 14,3% | P31: =IFERROR(_xlfn.XLOOKUP(_xlfn.XLOOKUP($A31,P$3:P$23,$A$3:$A$23),utility!$A$3:$A$23,utility!P$3:P$23)&" | "&ROUND(COUNTIF(P$3:P$23,$A31)/21,3)*100&"%","") -> 5-10m | 47,6% | Q31: =IFERROR(_xlfn.XLOOKUP(_xlfn.XLOOKUP($A31,Q$3:Q$23,$A$3:$A$23),utility!$A$3:$A$23,utility!Q$3:Q$23)&" | "&ROUND(COUNTIF(Q$3:Q$23,$A31)/21,3)*100&"%","") -> 5-10m | 9,5% | R31: =IFERROR(_xlfn.XLOOKUP(_xlfn.XLOOKUP($A31,R$3:R$23,$A$3:$A$23),utility!$A$3:$A$23,utility!R$3:R$23)&" | "&ROUND(COUNTIF(R$3:R$23,$A31)/21,3)*100&"%","") | ... AP31: =IFERROR(_xlfn.XLOOKUP(_xlfn.XLOOKUP($A31,AP$3:AP$23,$A$3:$A$23),utility!$A$3:$A$23,utility!AP$3:AP$23)&" | "&ROUND(COUNTIF(AP$3:AP$23,$A31)/21,3)*100&"%","") -> 4 | 9,5% | AW31: S3 | AX31: P1 | AY31: =AVERAGE(_xlfn.TEXTAFTER(BL16,"| "),_xlfn.TEXTAFTER(BM17,"| "),_xlfn.TEXTAFTER(BN19,"| ")) -> #N/A | AZ31: =AVERAGE(BL23,BM23,BN23) -> #DIV/0! | BA31: =SUM(100%-AZ31) -> #DIV/0!
A32: A005 | H32: =IFERROR(_xlfn.XLOOKUP(_xlfn.XLOOKUP($A32,H$3:H$23,$A$3:$A$23),utility!$A$3:$A$23,utility!H$3:H$23)&" | "&ROUND(COUNTIF(H$3:H$23,$A32)/21,3)*100&"%","") -> 0 - 5 m | 4,8% | I32: =IFERROR(_xlfn.XLOOKUP(_xlfn.XLOOKUP($A32,I$3:I$23,$A$3:$A$23),utility!$A$3:$A$23,utility!I$3:I$23)&" | "&ROUND(COUNTIF(I$3:I$23,$A32)/21,3)*100&"%","") -> 0-5m | 28,6% | J32: =IFERROR(_xlfn.XLOOKUP(_xlfn.XLOOKUP($A32,J$3:J$23,$A$3:$A$23),utility!$A$3:$A$23,utility!J$3:J$23)&" | "&ROUND(COUNTIF(J$3:J$23,$A32)/21,3)*100&"%","") -> 0-5m | 95,2% | K32: =IFERROR(_xlfn.XLOOKUP(_xlfn.XLOOKUP($A32,K$3:K$23,$A$3:$A$23),utility!$A$3:$A$23,utility!K$3:K$23)&" | "&ROUND(COUNTIF(K$3:K$23,$A32)/21,3)*100&"%","") | L32: =IFERROR(_xlfn.XLOOKUP(_xlfn.XLOOKUP($A32,L$3:L$23,$A$3:$A$23),utility!$A$3:$A$23,utility!L$3:L$23)&" | "&ROUND(COUNTIF(L$3:L$23,$A32)/21,3)*100&"%","") | M32: =IFERROR(_xlfn.XLOOKUP(_xlfn.XLOOKUP($A32,M$3:M$23,$A$3:$A$23),utility!$A$3:$A$23,utility!M$3:M$23)&" | "&ROUND(COUNTIF(M$3:M$23,$A32)/21,3)*100&"%","") | N32: =IFERROR(_xlfn.XLOOKUP(_xlfn.XLOOKUP($A32,N$3:N$23,$A$3:$A$23),utility!$A$3:$A$23,utility!N$3:N$23)&" | "&ROUND(COUNTIF(N$3:N$23,$A32)/21,3)*100&"%","") | O32: =IFERROR(_xlfn.XLOOKUP(_xlfn.XLOOKUP($A32,O$3:O$23,$A$3:$A$23),utility!$A$3:$A$23,utility!O$3:O$23)&" | "&ROUND(COUNTIF(O$3:O$23,$A32)/21,3)*100&"%","") | ... AP32: =IFERROR(_xlfn.XLOOKUP(_xlfn.XLOOKUP($A32,AP$3:AP$23,$A$3:$A$23),utility!$A$3:$A$23,utility!AP$3:AP$23)&" | "&ROUND(COUNTIF(AP$3:AP$23,$A32)/21,3)*100&"%","") -> 5 | 4,8%
A33: A006 | H33: =IFERROR(_xlfn.XLOOKUP(_xlfn.XLOOKUP($A33,H$3:H$23,$A$3:$A$23),utility!$A$3:$A$23,utility!H$3:H$23)&" | "&ROUND(COUNTIF(H$3:H$23,$A33)/21,3)*100&"%","") | I33: =IFERROR(_xlfn.XLOOKUP(_xlfn.XLOOKUP($A33,I$3:I$23,$A$3:$A$23),utility!$A$3:$A$23,utility!I$3:I$23)&" | "&ROUND(COUNTIF(I$3:I$23,$A33)/21,3)*100&"%","") | J33: 0 | K33: =IFERROR(_xlfn.XLOOKUP(_xlfn.XLOOKUP($A33,K$3:K$23,$A$3:$A$23),utility!$A$3:$A$23,utility!K$3:K$23)&" | "&ROUND(COUNTIF(K$3:K$23,$A33)/21,3)*100&"%","") | L33: =IFERROR(_xlfn.XLOOKUP(_xlfn.XLOOKUP($A33,L$3:L$23,$A$3:$A$23),utility!$A$3:$A$23,utility!L$3:L$23)&" | "&ROUND(COUNTIF(L$3:L$23,$A33)/21,3)*100&"%","") | M33: =IFERROR(_xlfn.XLOOKUP(_xlfn.XLOOKUP($A33,M$3:M$23,$A$3:$A$23),utility!$A$3:$A$23,utility!M$3:M$23)&" | "&ROUND(COUNTIF(M$3:M$23,$A33)/21,3)*100&"%","") | N33: =IFERROR(_xlfn.XLOOKUP(_xlfn.XLOOKUP($A33,N$3:N$23,$A$3:$A$23),utility!$A$3:$A$23,utility!N$3:N$23)&" | "&ROUND(COUNTIF(N$3:N$23,$A33)/21,3)*100&"%","") | O33: =IFERROR(_xlfn.XLOOKUP(_xlfn.XLOOKUP($A33,O$3:O$23,$A$3:$A$23),utility!$A$3:$A$23,utility!O$3:O$23)&" | "&ROUND(COUNTIF(O$3:O$23,$A33)/21,3)*100&"%","") | P33: =IFERROR(_xlfn.XLOOKUP(_xlfn.XLOOKUP($A33,P$3:P$23,$A$3:$A$23),utility!$A$3:$A$23,utility!P$3:P$23)&" | "&ROUND(COUNTIF(P$3:P$23,$A33)/21,3)*100&"%","") | Q33: =IFERROR(_xlfn.XLOOKUP(_xlfn.XLOOKUP($A33,Q$3:Q$23,$A$3:$A$23),utility!$A$3:$A$23,utility!Q$3:Q$23)&" | "&ROUND(COUNTIF(Q$3:Q$23,$A33)/21,3)*100&"%","") | R33: =IFERROR(_xlfn.XLOOKUP(_xlfn.XLOOKUP($A33,R$3:R$23,$A$3:$A$23),utility!$A$3:$A$23,utility!R$3:R$23)&" | "&ROUND(COUNTIF(R$3:R$23,$A33)/21,3)*100&"%","") -> Die Objekte sind gleich nah | 14,3% | ... AP33: =IFERROR(_xlfn.XLOOKUP(_xlfn.XLOOKUP($A33,AP$3:AP$23,$A$3:$A$23),utility!$A$3:$A$23,utility!AP$3:AP$23)&" | "&ROUND(COUNTIF(AP$3:AP$23,$A33)/21,3)*100&"%","") -> 6 | 4,8%
A34: A007 | H34: =IFERROR(_xlfn.XLOOKUP(_xlfn.XLOOKUP($A34,H$3:H$23,$A$3:$A$23),utility!$A$3:$A$23,utility!H$3:H$23)&" | "&ROUND(COUNTIF(H$3:H$23,$A34)/21,3)*100&"%","") | I34: =IFERROR(_xlfn.XLOOKUP(_xlfn.XLOOKUP($A34,I$3:I$23,$A$3:$A$23),utility!$A$3:$A$23,utility!I$3:I$23)&" | "&ROUND(COUNTIF(I$3:I$23,$A34)/21,3)*100&"%","") | J34: =IFERROR(_xlfn.XLOOKUP(_xlfn.XLOOKUP($A34,J$3:J$23,$A$3:$A$23),utility!$A$3:$A$23,utility!J$3:J$23)&" | "&ROUND(COUNTIF(J$3:J$23,$A34)/21,3)*100&"%","") | K34: =IFERROR(_xlfn.XLOOKUP(_xlfn.XLOOKUP($A34,K$3:K$23,$A$3:$A$23),utility!$A$3:$A$23,utility!K$3:K$23)&" | "&ROUND(COUNTIF(K$3:K$23,$A34)/21,3)*100&"%","") | L34: =IFERROR(_xlfn.XLOOKUP(_xlfn.XLOOKUP($A34,L$3:L$23,$A$3:$A$23),utility!$A$3:$A$23,utility!L$3:L$23)&" | "&ROUND(COUNTIF(L$3:L$23,$A34)/21,3)*100&"%","") | M34: =IFERROR(_xlfn.XLOOKUP(_xlfn.XLOOKUP($A34,M$3:M$23,$A$3:$A$23),utility!$A$3:$A$23,utility!M$3:M$23)&" | "&ROUND(COUNTIF(M$3:M$23,$A34)/21,3)*100&"%","") | N34: =IFERROR(_xlfn.XLOOKUP(_xlfn.XLOOKUP($A34,N$3:N$23,$A$3:$A$23),utility!$A$3:$A$23,utility!N$3:N$23)&" | "&ROUND(COUNTIF(N$3:N$23,$A34)/21,3)*100&"%","") | O34: =IFERROR(_xlfn.XLOOKUP(_xlfn.XLOOKUP($A34,O$3:O$23,$A$3:$A$23),utility!$A$3:$A$23,utility!O$3:O$23)&" | "&ROUND(COUNTIF(O$3:O$23,$A34)/21,3)*100&"%","") | ... AP34: =IFERROR(_xlfn.XLOOKUP(_xlfn.XLOOKUP($A34,AP$3:AP$23,$A$3:$A$23),utility!$A$3:$A$23,utility!AP$3:AP$23)&" | "&ROUND(COUNTIF(AP$3:AP$23,$A34)/21,3)*100&"%","") -> 7 | 57,1%
H36: =SUM(_xlfn.TEXTAFTER(H28,"| "),_xlfn.TEXTAFTER(H29,"| ")) -> 0.333 | I36: =SUM(_xlfn.TEXTAFTER(I30,"| "),_xlfn.TEXTAFTER(I31,"| ")) -> 0.667 | J36: =SUM(_xlfn.TEXTAFTER(J32,"| "),J33) -> 0.952 | O36: =SUM(_xlfn.TEXTAFTER(O28," | "),_xlfn.TEXTAFTER(O29," | ")) -> 0.381 | P36: =SUM(_xlfn.TEXTAFTER(P30," | "),_xlfn.TEXTAFTER(P31," | ")) -> 0.809 | Q36: =SUM(_xlfn.TEXTAFTER(Q32," | "),_xlfn.TEXTAFTER(Q31," | ")) -> 1 | V36: =SUM(_xlfn.TEXTAFTER(V29," | "),_xlfn.TEXTAFTER(V28," | ")) -> 0.381 | W36: =SUM(_xlfn.TEXTAFTER(W30," | "),_xlfn.TEXTAFTER(W31," | ")) -> 0.857 | X36: =SUM(_xlfn.TEXTAFTER(X32," | "),_xlfn.TEXTAFTER(X31," | ")) -> 1
G40: Ergebnisse: Metrische Fragen
G41: Szenario | H41: Phase | I41: Anteil GT-Klasse | J41: Anteil GT +/-1 | K41: Streuung
G42: S1 | H42: P1 | I42: =AVERAGE(_xlfn.TEXTAFTER(H29,"| "),_xlfn.TEXTAFTER(I30,"| "),_xlfn.TEXTAFTER(J32,"| ")) -> 0.476 | J42: =AVERAGE(H36,I36,J36) -> 0.65066667 | K42: =SUM(100%-J42) -> 0.34933333 | AG42: Ergebnisse: Subjektive S2_P2 | AH42: Spalte1 | AI42: Spalte2 | AJ42: Spalte3 | AL42: Ergebnisse: Subjektive S3_P2 | AM42: Spalte1 | AN42: Spalte2 | AO42: Spalte3
G43: S2 | H43: P1 | I43: =AVERAGE(_xlfn.TEXTAFTER(O29,"| "),_xlfn.TEXTAFTER(P30,"| "),_xlfn.TEXTAFTER(Q32,"| ")) -> 0.52366667 | J43: =AVERAGE(O36,P36,Q36) -> 0.73 | K43: =SUM(100%-J43) -> 0.27 | AG43: Fragen | AH43: Median | AI43: Hauptanteil | AJ43: Streuung | AL43: Fragen | AM43: Median | AN43: Hauptanteil | AO43: Streuung
G44: S3 | H44: P1 | I44: =AVERAGE(_xlfn.TEXTAFTER(V29,"| "),_xlfn.TEXTAFTER(W30,"| "),_xlfn.TEXTAFTER(X32,"| ")) -> 0.46033333 | J44: =AVERAGE(V36,W36,X36) -> 0.746 | K44: =SUM(100%-J44) -> 0.254 | AG44: Tiefenwahrnehmung klar erkennbar | AH44: {=MEDIAN(VALUE(RIGHT(AH3:AH23,2)))} -> 6 | AI44: {=_xlfn.MODE.SNGL(VALUE(RIGHT(AH3:AH23,2)))} -> 7 | AJ44: {=_xlfn.STDEV.S(VALUE(RIGHT(AH3:AH23,2)))} -> 1.3219754 | AL44: Tiefenwahrnehmung klar erkennbar | AM44: {=MEDIAN(VALUE(RIGHT(AM3:AM23,2)))} -> 7 | AN44: {=_xlfn.MODE.SNGL(VALUE(RIGHT(AM3:AM23,2)))} -> 7 | AO44: {=_xlfn.STDEV.S(VALUE(RIGHT(AM3:AM23,2)))} -> 0.8135753
AG45: Verzerrungen beim Bewegen | AH45: {=MEDIAN(VALUE(RIGHT(AI3:AI23,2)))} -> 2 | AI45: {=_xlfn.MODE.SNGL(VALUE(RIGHT(AI3:AI23,2)))} -> 1 | AJ45: {=_xlfn.STDEV.S(VALUE(RIGHT(AI3:AI23,2)))} -> 1.4605935 | AL45: Verzerrungen beim Bewegen | AM45: {=MEDIAN(VALUE(RIGHT(AN3:AN23,2)))} -> 1 | AN45: {=_xlfn.MODE.SNGL(VALUE(RIGHT(AN3:AN23,2)))} -> 1 | AO45: {=_xlfn.STDEV.S(VALUE(RIGHT(AN3:AN23,2)))} -> 1.8439089
AG46: Tiefenwirkung realistisch | AH46: {=MEDIAN(VALUE(RIGHT(AJ3:AJ23,2)))} -> 5 | AI46: {=_xlfn.MODE.SNGL(VALUE(RIGHT(AJ3:AJ23,2)))} -> 7 | AJ46: {=_xlfn.STDEV.S(VALUE(RIGHT(AJ3:AJ23,2)))} -> 1.8516402 | AL46: Tiefenwirkung realistisch | AM46: {=MEDIAN(VALUE(RIGHT(AO3:AO23,2)))} -> 6 | AN46: {=_xlfn.MODE.SNGL(VALUE(RIGHT(AO3:AO23,2)))} -> 7 | AO46: {=_xlfn.STDEV.S(VALUE(RIGHT(AO3:AO23,2)))} -> 1.503963
G47: Ergebnisse: Relativ Schätzung | AG47: Szene läuft flüssig | AH47: {=MEDIAN(VALUE(RIGHT(AK3:AK23,2)))} -> 7 | AI47: {=_xlfn.MODE.SNGL(VALUE(RIGHT(AK3:AK23,2)))} -> 7 | AJ47: {=_xlfn.STDEV.S(VALUE(RIGHT(AK3:AK23,2)))} -> 2.2488092 | AL47: Szene läuft flüssig | AM47: {=MEDIAN(VALUE(RIGHT(AP3:AP23,2)))} -> 7 | AN47: {=_xlfn.MODE.SNGL(VALUE(RIGHT(AP3:AP23,2)))} -> 7 | AO47: {=_xlfn.STDEV.S(VALUE(RIGHT(AP3:AP23,2)))} -> 2.4270303
G48: Szenario | H48: Phase | I48: Korrekte Ordnung | J48: Falsche Ordnung | K48: Unsicher
G49: S1 | H49: P1 | I49: =AVERAGE(_xlfn.TEXTAFTER(K28," | "),_xlfn.TEXTAFTER(L28," | "),_xlfn.TEXTAFTER(M29," | ")) -> 0.857 | J49: =AVERAGE( VALUE(_xlfn.TEXTAFTER(K31," | ")), VALUE(_xlfn.TEXTAFTER(L29," | ")) + VALUE(_xlfn.TEXTAFTER(L31," | ")), VALUE(_xlfn.TEXTAFTER(M31," | ")) ) -> 0.143 | K49: 0
G50: S2 | H50: P1 | I50: =AVERAGE(_xlfn.TEXTAFTER(R32," | "),_xlfn.TEXTAFTER(S32," | "),_xlfn.TEXTAFTER(T32," | ")) -> 0.63533333 | J50: =AVERAGE( _xlfn.TEXTAFTER(R33," | "),_xlfn.TEXTAFTER(S33," | ")+_xlfn.TEXTAFTER(S31," | "),_xlfn.TEXTAFTER(T33," | ")+_xlfn.TEXTAFTER(T31," | ")) -> 0.333 | K50: 0.03
G51: S3 | H51: P1 | I51: =AVERAGE(_xlfn.TEXTAFTER(Y31," | "),_xlfn.TEXTAFTER(Z31," | "),_xlfn.TEXTAFTER(AA32," | ")) -> 0.84133333 | J51: =AVERAGE( (Y30), _xlfn.TEXTAFTER(Z33," | "), _xlfn.TEXTAFTER(AA33," | ")+_xlfn.TEXTAFTER(AA31," | ") ) -> 0.159 | K51: 0
G54: Ergebnisse: Subjektive S1_P2 | H54: Spalte1 | I54: Spalte2 | J54: Spalte3
...

Sheet utility
A2: Antwort ID | B2: Wie alt sind Sie? | C2: Wie häufig nutzen Sie 3D-Inhalte oder 3D-Anwendungen? (z. B. 3D-Videospiele, 3D-Animationen in Filmen/Serien) | D2: Wie groß ist Ihre Bildschirmgröße, auf der Sie die Studie durchführen? | E2: Wie hoch ist ihre Downloadgeschwindigkeit, mit der sie die Szenarien ansehen? | F2: Hat der Computer/Laptop, mit dem sie die Studie durchführen, eine zusätzliche Grafikkarte (dedizierte Grafikkarte)? | G2: Bitte schauen Sie sich jetzt das erste Szenario an, und beantworte danach die folgenden Fragen Sie können jederzeit sich das Szenario nochmal ansehen, um die Fragen besser zu beantworten. | H2: Die Entfernung zwischen dem Menschen im grauen Bereich und der Säule im blauen Bereich würde ich wie folgt einschätzen. [] | I2: Wie weit entfernt ist die Säule im grünen Bereich von Ihrer aktuellen Position (aus Ihrer Sicht/POV)? [] | J2: Wie weit erscheint ihnen der Abstand der Kiste im grauen Bereich? [] | K2: Direkt nach dem Neustart (Reset) des Szenarios: Welches Objekt ist näher an Ihrer Startposition? | L2: Direkt nach dem Neustart (Reset) des Szenarios: Welches Objekt ist näher an Ihrer Startposition? | M2: Direkt nach dem Neustart (Reset) des Szenarios: Welches Objekt ist näher an Ihrer Startposition? | N2: Bitte schauen Sie sich jetzt das Zweite Szenario an, und beantworte danach die folgenden Fragen Sie können jederzeit sich das Szenario nochmal ansehen, um die Fragen besser zu beantworten. Bitte bewerten Sie dieses Szenario unabhängig von den vorherigen. Jede Szene kann eine andere Tiefenwirkung haben. | O2: Die Entfernung zwischen dem Menschen im grauen Bereich und der Säule im blauen Bereich würde ich wie folgt einschätzen. [] | P2: Wie weit entfernt ist die Säule im grünen Bereich von Ihrer aktuellen Position (aus Ihrer Sicht/POV)? [] | Q2: Wie weit erscheint ihnen der Abstand der Kiste im grauen Bereich? [] | R2: Direkt nach dem Neustart (Reset) des Szenarios: Welches Objekt ist näher an Ihrer Startposition? | S2: Direkt nach dem Neustart (Reset) des Szenarios: Welches Objekt ist näher an Ihrer Startposition? | T2: Direkt nach dem Neustart (Reset) des Szenarios: Welches Objekt ist näher an Ihrer Startposition? | U2: Bitte schauen Sie sich jetzt das Dritte Szenario an, und beantworte danach die folgenden Fragen Sie können jederzeit sich das Szenario nochmal ansehen, um die Fragen besser zu beantworten. Bitte bewerten Sie dieses Szenario unabhängig von den vorherigen. Jede Szene kann eine andere Tiefenwirkung haben. | V2: Die Entfernung zwischen dem Menschen im grauen Bereich und der Säule im blauen Bereich würde ich wie folgt einschätzen. [] | W2: Wie weit entfernt ist die Säule im grünen Bereich von Ihrer aktuellen Position (aus Ihrer Sicht/POV)? [] | X2: Wie weit erscheint ihnen der Abstand der Kiste im grauen Bereich? [] | Y2: Direkt nach dem Neustart (Reset) des Szenarios: Welches Objekt ist näher an Ihrer Startposition? | Z2: Direkt nach dem Neustart (Reset) des Szenarios: Welches Objekt ist näher an Ihrer Startposition? | AA2: Direkt nach dem Neustart (Reset) des Szenarios: Welches Objekt ist näher an Ihrer Startposition? | AB2: Bitte schauen Sie sich jetzt das erste Szenario an, und beantworte danach die folgenden Fragen Sie können jederzeit sich das Szenario nochmal ansehen, um die Fragen besser zu beantworten. Bitte bewerten Sie dieses Szenario unabhängig von den vorherigen. Jede Szene kann eine andere Tiefenwirkung haben. | AC2: Eine eindeutige und deutliche Tiefenwahrnehmung zwischen den Bereichen Grau, Grün und Blau ist klar erkennbar? [] | AD2: Beim Bewegen fallen Verzerrungen oder Verformungen der Umgebung stark auf. [] | AE2: Die räumliche Tiefenwahrnehmung wirkt realistisch. [] | AF2: Nach dem Laden läuft die Szene flüssig und ich habe kein Ruckeln oder ein eingefrorenes Bild. (Latenzen) [] | AG2: Bitte schauen Sie sich jetzt das erste Szenario an, und beantworte danach die folgenden Fragen Sie können jederzeit sich das Szenario nochmal ansehen, um die Fragen besser zu beantworten. Bitte bewerten Sie dieses Szenario unabhängig von den vorherigen. Jede Szene kann eine andere Tiefenwirkung haben. | AH2: Eine eindeutige und deutliche Tiefenwahrnehmung zwischen den Bereichen Grau, Grün und Blau ist klar erkennbar? [] | AI2: Beim Bewegen fallen Verzerrungen oder Verformungen der Umgebung stark auf. [] | AJ2: Die räumliche Tiefenwahrnehmung wirkt realistisch. [] | AK2: Nach dem Laden läuft die Szene flüssig und ich habe kein Ruckeln oder ein eingefrorenes Bild. (Latenzen) [] | AL2: Bitte schauen Sie sich jetzt das erste Szenario an, und beantworte danach die folgenden Fragen Sie können jederzeit sich das Szenario nochmal ansehen, um die Fragen besser zu beantworten. Bitte bewerten Sie dieses Szenario unabhängig von den vorherigen. Jede Szene kann eine andere Tiefenwirkung haben. | AM2: Eine eindeutige und deutliche Tiefenwahrnehmung zwischen den Bereichen Grau, Grün und Blau ist klar erkennbar? [] | AN2: Beim Bewegen fallen Verzerrungen oder Verformungen der Umgebung stark auf. [] | AO2: Die räumliche Tiefenwahrnehmung wirkt realistisch. [] | AP2: Nach dem Laden läuft die Szene flüssig und ich habe kein Ruckeln oder ein eingefrorenes Bild. (Latenzen) []
A3: 5 | B3: 28 | C3: 4 | D3: 13-24" Zoll | E3: 50-100 Mbit/s | F3: Ja, eine Grafikkarte ist vorhanden. | G3: Ja ich hab das szenario gesehen und weiter | H3: 0 - 5 m | I3: 5-10m | J3: 0-5m | K3: Die Kiste vor dem Bett im Holzraum | L3: Die Objekte sind gleich nah | M3: Die Säule im grauen Bereich | N3: Ja ich hab das szenario gesehen und weiter | O3: 10-15m | P3: 5-10m | Q3: 0-5m | R3: Das gelbe Schild im weißen Raum | S3: Die fässer auf der terasse vom Haus | T3: Die Kiste im grauen Bereich | U3: Ja ich hab das szenario gesehen und weiter | V3: 20-25m | W3: 10-15m | X3: 5-10m | Y3: Die Kiste vor dem Bett im Holzraum | Z3: Die Haustür vom Haus | AA3: Die Säule im grauen Bereich | AB3: Ja ich hab das szenario gesehen und weiter | AC3: 3 | AD3: 5 | AE3: 2 | AF3: 6 | AG3: Ja ich hab das szenario gesehen und weiter | AH3: 5 | AI3: 3 | AJ3: 4 | AK3: 7 | AL3: Ja ich hab das szenario gesehen und weiter | AM3: 5 | AN3: 5 | AO3: 5 | AP3: 4
A4: 7 | B4: 26 | C4: 2 | D4: 13-24" Zoll | E4: 250 Mbit/s oder mehr | F4: Nein, ich habe keine. | G4: Ja ich hab das szenario gesehen und weiter | H4: 15 - 20 m | I4: 5-10m | J4: 0-5m | K4: Die Kiste vor dem Bett im Holzraum | L4: Die Objekte sind gleich nah | M4: Die Säule im grauen Bereich | N4: Ja ich hab das szenario gesehen und weiter | O4: 10-15m | P4: 5-10m | Q4: 0-5m | R4: Die Objekte sind gleich nah | S4: Die Objekte sind gleich nah | T4: Die Säule im grauen Bereich | U4: Ja ich hab das szenario gesehen und weiter | V4: 10-15m | W4: 5-10m | X4: 0-5m | Y4: Die Kiste vor dem Bett im Holzraum | Z4: Die Objekte sind gleich nah | AA4: Die Säule im grauen Bereich | AB4: Ja ich hab das szenario gesehen und weiter | AC4: 6 | AD4: 7 | AE4: 4 | AF4: 7 | AG4: Ja ich hab das szenario gesehen und weiter | AH4: 7 | AI4: 1 | AJ4: 6 | AK4: 7 | AL4: Ja ich hab das szenario gesehen und weiter | AM4: 7 | AN4: 1 | AO4: 6 | AP4: 7
A5: 8 | B5: 26 | C5: 4 | D5: Größer als 24" Zoll | E5: 50-100 Mbit/s | F5: Ja, eine Grafikkarte ist vorhanden. | G5: Ja ich hab das szenario gesehen und weiter | H5: 10 - 15 m | I5: 5-10m | J5: 0-5m | K5: Die Kiste vor dem Bett im Holzraum | L5: Die Haustür vom Haus | M5: Die Säule im grauen Bereich | N5: Ja ich hab das szenario gesehen und weiter | O5: 10-15m | P5: 10-15m | Q5: 0-5m | R5: Das gelbe Schild im weißen Raum | S5: Die Objekte sind gleich nah | T5: Die Säule im grauen Bereich | U5: Ja ich hab das szenario gesehen und weiter | V5: 10-15m | W5: 5-10m | X5: 0-5m | Y5: Die Kiste vor dem Bett im Holzraum | Z5: Die Objekte sind gleich nah | AA5: Die Säule im grauen Bereich | AB5: Ja ich hab das szenario gesehen und weiter | AC5: 7 | AD5: 2 | AE5: 6 | AF5: 7 | AG5: Ja ich hab das szenario gesehen und weiter | AH5: 7 | AI5: 2 | AJ5: 4 | AK5: 7 | AL5: Ja ich hab das szenario gesehen und weiter | AM5: 7 | AN5: 2 | AO5: 6 | AP5: 7
A6: 9 | B6: 25 | C6: 3 | D6: Größer als 24" Zoll | E6: 50-100 Mbit/s | F6: Ja, eine Grafikkarte ist vorhanden. | G6: Ja ich hab das szenario gesehen und weiter | H6: 20 - 25 m | I6: 20-25m | J6: 0-5m | K6: Die Kiste vor dem Bett im Holzraum | L6: Die Haustür vom Haus | M6: Die Säule im grauen Bereich | N6: Ja ich hab das szenario gesehen und weiter | O6: 10-15m | P6: 5-10m | Q6: 0-5m | R6: Die Objekte sind gleich nah | S6: Die fässer auf der terasse vom Haus | T6: Die Objekte sind gleich nah | U6: Ja ich hab das szenario gesehen und weiter | V6: 0-5m | W6: 5-10m | X6: 0-5m | Y6: Die Kiste vor dem Bett im Holzraum | Z6: Die Objekte sind gleich nah | AA6: Die Säule im grauen Bereich | AB6: Ja ich hab das szenario gesehen und weiter | AC6: 6 | AD6: 5 | AE6: 1 | AF6: 1 | AG6: Ja ich hab das szenario gesehen und weiter | AH6: 4 | AI6: 1 | AJ6: 1 | AK6: 1 | AL6: Ja ich hab das szenario gesehen und weiter | AM6: 7 | AN6: 7 | AO6: 3 | AP6: 7
A7: 11 | B7: 27 | C7: 4 | D7: Größer als 24" Zoll | E7: 16-50 Mbit/s | F7: Ja, eine Grafikkarte ist vorhanden. | G7: Ja ich hab das szenario gesehen und weiter | H7: 10 - 15 m | I7: 5-10m | J7: 0-5m | K7: Die Kiste vor dem Bett im Holzraum | L7: Die Haustür vom Haus | M7: Die Objekte sind gleich nah | N7: Ja ich hab das szenario gesehen und weiter | O7: 10-15m | P7: 5-10m | Q7: 0-5m | R7: Das gelbe Schild im weißen Raum | S7: Die Objekte sind gleich nah | T7: Die Säule im grauen Bereich | U7: Ja ich hab das szenario gesehen und weiter | V7: 10-15m | W7: 5-10m | X7: 0-5m | Y7: Die Kiste vor dem Bett im Holzraum | Z7: Die Haustür vom Haus | AA7: Die Objekte sind gleich nah | AB7: Ja ich hab das szenario gesehen und weiter | AC7: 5 | AD7: 1 | AE7: 2 | AF7: 7 | AG7: Ja ich hab das szenario gesehen und weiter | AH7: 5 | AI7: 4 | AJ7: 2 | AK7: 6 | AL7: Ja ich hab das szenario gesehen und weiter | AM7: 5 | AN7: 1 | AO7: 2 | AP7: 4
A8: 12 | B8: 28 | C8: 1 | D8: 13-24" Zoll | E8: 16-50 Mbit/s | F8: Nein, ich habe keine. | G8: Ja ich hab das szenario gesehen und weiter | H8: 20 - 25 m | I8: 10-15m | J8: 0-5m | K8: Die Kiste vor dem Bett im Holzraum | L8: Die Objekte sind gleich nah | M8: Die Säule im grauen Bereich | N8: Ja ich hab das szenario gesehen und weiter | O8: 15-20m | P8: 10-15m | Q8: 0-5m | R8: Die Objekte sind gleich nah | S8: Die Objekte sind gleich nah | T8: Die Säule im grauen Bereich | U8: Ja ich hab das szenario gesehen und weiter | V8: 15-20m | W8: 10-15m | X8: 0-5m | Y8: Die Kiste vor dem Bett im Holzraum | Z8: Die Haustür vom Haus | AA8: Die Säule im grauen Bereich | AB8: Ja ich hab das szenario gesehen und weiter | AC8: 7 | AD8: 1 | AE8: 7 | AF8: 7 | AG8: Ja ich hab das szenario gesehen und weiter | AH8: 5 | AI8: 5 | AJ8: 3 | AK8: 2 | AL8: Ja ich hab das szenario gesehen und weiter | AM8: 6 | AN8: 2 | AO8: 5 | AP8: 6
A9: 13 | B9: 25 | C9: 5 | D9: Größer als 24" Zoll | E9: 100-250 Mbit/s | F9: Ja, eine Grafikkarte ist vorhanden. | G9: Ja ich hab das szenario gesehen und weiter | H9: 5-10 m | I9: 0-5m | J9: 0-5m | K9: Die Kiste vor dem Bett im Holzraum | L9: Die gelbe Ente im Pavillon | M9: Die Säule im grauen Bereich | N9: Ja ich hab das szenario gesehen und weiter | O9: 5-10m | P9: 0-5m | Q9: 0-5m | R9: Das gelbe Schild im weißen Raum | S9: Die gelbe Ente im Pavillon | T9: Die Säule im grauen Bereich | U9: Ja ich hab das szenario gesehen und weiter | V9: 5-10m | W9: 0-5m | X9: 0-5m | Y9: Die Kiste vor dem Bett im Holzraum | Z9: Die Objekte sind gleich nah | AA9: Die Säule im grauen Bereich | AB9: Ja ich hab das szenario gesehen und weiter | AC9: 7 | AD9: 7 | AE9: 2 | AF9: 7 | AG9: Ja ich hab das szenario gesehen und weiter | AH9: 7 | AI9: 1 | AJ9: 6 | AK9: 7 | AL9: Ja ich hab das szenario gesehen und weiter | AM9: 7 | AN9: 1 | AO9: 7 | AP9: 7
A10: 15 | B10: 27 | C10: 1 | D10: 13-24" Zoll | E10: Weiß ich nicht. | F10: Ich weiß es nicht | G10: Ja ich hab das szenario gesehen und weiter | H10: 5-10 m | I10: 0-5m | J10: 0-5m | K10: Die Kiste vor dem Bett im Holzraum | L10: Die Haustür vom Haus | M10: Die Säule im grauen Bereich | N10: Ja ich hab das szenario gesehen und weiter | O10: 15-20m | P10: 15-20m | Q10: 5-10m | R10: Das gelbe Schild im weißen Raum | S10: Die Objekte sind gleich nah | T10: Die Säule im grauen Bereich | U10: Ja ich hab das szenario gesehen und weiter | V10: 20-25m | W10: 10-15m | X10: 5-10m | Y10: Die Kiste vor dem Bett im Holzraum | Z10: Die Haustür vom Haus | AA10: Die Säule im grauen Bereich | AB10: Ja ich hab das szenario gesehen und weiter | AC10: 5 | AD10: 4 | AE10: 4 | AF10: 6 | AG10: Ja ich hab das szenario gesehen und weiter | AH10: 6 | AI10: 4 | AJ10: 4 | AK10: 3 | AL10: Ja ich hab das szenario gesehen und weiter | AM10: 7 | AN10: 4 | AO10: 4 | AP10: 1
A11: 17 | B11: 29 | C11: 5 | D11: Größer als 24" Zoll | E11: 50-100 Mbit/s | F11: Ja, eine Grafikkarte ist vorhanden. | G11: Ja ich hab das szenario gesehen und weiter | H11: 10 - 15 m | I11: 10-15m | J11: 0-5m | K11: Die Kiste vor dem Bett im Holzraum | L11: Die Objekte sind gleich nah | M11: Die Säule im grauen Bereich | N11: Ja ich hab das szenario gesehen und weiter | O11: 10-15m | P11: 5-10m | Q11: 0-5m | R11: Das gelbe Schild im weißen Raum | S11: Die gelbe Ente im Pavillon | T11: Die Säule im grauen Bereich | U11: Ja ich hab das szenario gesehen und weiter | V11: 10-15m | W11: 5-10m | X11: 0-5m | Y11: Die Kiste vor dem Bett im Holzraum | Z11: Die Haustür vom Haus | AA11: Die Säule im grauen Bereich | AB11: Ja ich hab das szenario gesehen und weiter | AC11: 6 | AD11: 7 | AE11: 5 | AF11: 7 | AG11: Ja ich hab das szenario gesehen und weiter | AH11: 7 | AI11: 1 | AJ11: 7 | AK11: 7 | AL11: Ja ich hab das szenario gesehen und weiter | AM11: 7 | AN11: 1 | AO11: 7 | AP11: 7
A12: 19 | B12: 27 | C12: 2 | D12: Größer als 24" Zoll | E12: 100-250 Mbit/s | F12: Ja, eine Grafikkarte ist vorhanden. | G12: Ja ich hab das szenario gesehen und weiter | H12: 10 - 15 m | I12: 5-10m | J12: 0-5m | K12: Die Kiste vor dem Bett im Holzraum | L12: Die Haustür vom Haus | M12: Die Säule im grauen Bereich | N12: Ja ich hab das szenario gesehen und weiter | O12: 10-15m | P12: 5-10m | Q12: 0-5m | R12: Das gelbe Schild im weißen Raum | S12: Die Objekte sind gleich nah | T12: Die Säule im grauen Bereich | U12: Ja ich hab das szenario gesehen und weiter | V12: 10-15m | W12: 5-10m | X12: 0-5m | Y12: Die Kiste vor dem Bett im Holzraum | Z12: Die Haustür vom Haus | AA12: Die Säule im grauen Bereich | AB12: Ja ich hab das szenario gesehen und weiter | AC12: 3 | AD12: 6 | AE12: 2 | AF12: 7 | AG12: Ja ich hab das szenario gesehen und weiter | AH12: 5 | AI12: 1 | AJ12: 4 | AK12: 7 | AL12: Ja ich hab das szenario gesehen und weiter | AM12: 5 | AN12: 1 | AO12: 3 | AP12: 7
A13: 23 | B13: 33 | C13: 1 | D13: 13-24" Zoll | E13: 16-50 Mbit/s | F13: Ja, eine Grafikkarte ist vorhanden. | G13: Ja ich hab das szenario gesehen und weiter | H13: 5-10 m | I13: 10-15m | J13: 0-5m | K13: Die Kiste vor dem Bett im Holzraum | L13: Die Haustür vom Haus | M13: Die Objekte sind gleich nah | N13: Ja ich hab das szenario gesehen und weiter | O13: 5-10m | P13: 10-15m | Q13: 0-5m | R13: Das gelbe Schild im weißen Raum | S13: Die gelbe Ente im Pavillon | T13: Die Säule im grauen Bereich | U13: Ja ich hab das szenario gesehen und weiter | V13: 15-20m | W13: 5-10m | X13: 0-5m | Y13: Die Kiste vor dem Bett im Holzraum | Z13: Die Haustür vom Haus | AA13: Die Objekte sind gleich nah | AB13: Ja ich hab das szenario gesehen und weiter | AC13: 7 | AD13: 7 | AE13: 4 | AF13: 7 | AG13: Ja ich hab das szenario gesehen und weiter | AH13: 6 | AI13: 4 | AJ13: 3 | AK13: 7 | AL13: Ja ich hab das szenario gesehen und weiter | AM13: 7 | AN13: 1 | AO13: 7 | AP13: 7
A14: 26 | B14: 32 | C14: 3 | D14: Größer als 24" Zoll | E14: 50-100 Mbit/s | F14: Ja, eine Grafikkarte ist vorhanden. | G14: Ja ich hab das szenario gesehen und weiter | H14: 5-10 m | I14: 0-5m | J14: 0-5m | K14: Die Kiste vor dem Bett im Holzraum | L14: Die Haustür vom Haus | M14: Die Säule im grauen Bereich | N14: Ja ich hab das szenario gesehen und weiter | O14: 15-20m | P14: 10-15m | Q14: 0-5m | R14: Das gelbe Schild im weißen Raum | S14: Die gelbe Ente im Pavillon | T14: Die Säule im grauen Bereich | U14: Ja ich hab das szenario gesehen und weiter | V14: 15-20m | W14: 5-10m | X14: 0-5m | Y14: Die Kiste vor dem Bett im Holzraum | Z14: Die Haustür vom Haus | AA14: Die Säule im grauen Bereich | AB14: Ja ich hab das szenario gesehen und weiter | AC14: 2 | AD14: 7 | AE14: 3 | AF14: 4 | AG14: Ja ich hab das szenario gesehen und weiter | AH14: 7 | AI14: 2 | AJ14: 7 | AK14: 5 | AL14: Ja ich hab das szenario gesehen und weiter | AM14: 7 | AN14: 1 | AO14: 7 | AP14: 3
... A23: 39 | B23: 25 | C23: 5 | D23: 13-24" Zoll | E23: 50-100 Mbit/s | F23: Nein, ich habe keine. | G23: Ja ich hab das szenario gesehen und weiter | H23: 15 - 20 m | I23: 0-5m | J23: 0-5m | K23: Die Objekte sind gleich nah | L23: Die Haustür vom Haus | M23: Die Säule im grauen Bereich | N23: Ja ich hab das szenario gesehen und weiter | O23: 10-15m | P23: 5-10m | Q23: 0-5m | R23: Zu ungenau / Unsicher | S23: Zu ungenau / Unsicher | T23: Die Kiste im grauen Bereich | U23: Ja ich hab das szenario gesehen und weiter | V23: Weiß ich nicht | W23: Weiß ich nicht | X23: 0-5m | Y23: Die Kiste vor dem Bett im Holzraum | Z23: Die Objekte sind gleich nah | AA23: Die Säule im grauen Bereich | AB23: Ja ich hab das szenario gesehen und weiter | AC23: 6 | AD23: 4 | AE23: 5 | AF23: 7 | AG23: Ja ich hab das szenario gesehen und weiter | AH23: 5 | AI23: 2 | AJ23: 5 | AK23: 7 | AL23: Ja ich hab das szenario gesehen und weiter | AM23: 6 | AN23: 1 | AO23: 6 | AP23: 7
